{
  "cells": [
    {
      "cell_type": "code",
      "source": [
        "!pip install google-cloud-aiplatform"
      ],
      "metadata": {
        "colab": {
          "base_uri": "https://localhost:8080/"
        },
        "id": "BjYT9RjuWA1O",
        "outputId": "50dc89d6-98ae-408c-ddf0-215a4ce274ba"
      },
      "execution_count": 6,
      "outputs": [
        {
          "output_type": "stream",
          "name": "stdout",
          "text": [
            "Requirement already satisfied: google-cloud-aiplatform in /usr/local/lib/python3.10/dist-packages (1.70.0)\n",
            "Requirement already satisfied: google-api-core!=2.0.*,!=2.1.*,!=2.2.*,!=2.3.*,!=2.4.*,!=2.5.*,!=2.6.*,!=2.7.*,<3.0.0dev,>=1.34.1 in /usr/local/lib/python3.10/dist-packages (from google-api-core[grpc]!=2.0.*,!=2.1.*,!=2.2.*,!=2.3.*,!=2.4.*,!=2.5.*,!=2.6.*,!=2.7.*,<3.0.0dev,>=1.34.1->google-cloud-aiplatform) (2.19.2)\n",
            "Requirement already satisfied: google-auth<3.0.0dev,>=2.14.1 in /usr/local/lib/python3.10/dist-packages (from google-cloud-aiplatform) (2.27.0)\n",
            "Requirement already satisfied: proto-plus<2.0.0dev,>=1.22.3 in /usr/local/lib/python3.10/dist-packages (from google-cloud-aiplatform) (1.24.0)\n",
            "Requirement already satisfied: protobuf!=4.21.0,!=4.21.1,!=4.21.2,!=4.21.3,!=4.21.4,!=4.21.5,<6.0.0dev,>=3.20.2 in /usr/local/lib/python3.10/dist-packages (from google-cloud-aiplatform) (3.20.3)\n",
            "Requirement already satisfied: packaging>=14.3 in /usr/local/lib/python3.10/dist-packages (from google-cloud-aiplatform) (24.1)\n",
            "Requirement already satisfied: google-cloud-storage<3.0.0dev,>=1.32.0 in /usr/local/lib/python3.10/dist-packages (from google-cloud-aiplatform) (2.8.0)\n",
            "Requirement already satisfied: google-cloud-bigquery!=3.20.0,<4.0.0dev,>=1.15.0 in /usr/local/lib/python3.10/dist-packages (from google-cloud-aiplatform) (3.25.0)\n",
            "Requirement already satisfied: google-cloud-resource-manager<3.0.0dev,>=1.3.3 in /usr/local/lib/python3.10/dist-packages (from google-cloud-aiplatform) (1.12.5)\n",
            "Requirement already satisfied: shapely<3.0.0dev in /usr/local/lib/python3.10/dist-packages (from google-cloud-aiplatform) (2.0.6)\n",
            "Requirement already satisfied: pydantic<3 in /usr/local/lib/python3.10/dist-packages (from google-cloud-aiplatform) (2.9.2)\n",
            "Requirement already satisfied: docstring-parser<1 in /usr/local/lib/python3.10/dist-packages (from google-cloud-aiplatform) (0.16)\n",
            "Requirement already satisfied: googleapis-common-protos<2.0.dev0,>=1.56.2 in /usr/local/lib/python3.10/dist-packages (from google-api-core!=2.0.*,!=2.1.*,!=2.2.*,!=2.3.*,!=2.4.*,!=2.5.*,!=2.6.*,!=2.7.*,<3.0.0dev,>=1.34.1->google-api-core[grpc]!=2.0.*,!=2.1.*,!=2.2.*,!=2.3.*,!=2.4.*,!=2.5.*,!=2.6.*,!=2.7.*,<3.0.0dev,>=1.34.1->google-cloud-aiplatform) (1.65.0)\n",
            "Requirement already satisfied: requests<3.0.0.dev0,>=2.18.0 in /usr/local/lib/python3.10/dist-packages (from google-api-core!=2.0.*,!=2.1.*,!=2.2.*,!=2.3.*,!=2.4.*,!=2.5.*,!=2.6.*,!=2.7.*,<3.0.0dev,>=1.34.1->google-api-core[grpc]!=2.0.*,!=2.1.*,!=2.2.*,!=2.3.*,!=2.4.*,!=2.5.*,!=2.6.*,!=2.7.*,<3.0.0dev,>=1.34.1->google-cloud-aiplatform) (2.32.3)\n",
            "Requirement already satisfied: grpcio<2.0dev,>=1.33.2 in /usr/local/lib/python3.10/dist-packages (from google-api-core[grpc]!=2.0.*,!=2.1.*,!=2.2.*,!=2.3.*,!=2.4.*,!=2.5.*,!=2.6.*,!=2.7.*,<3.0.0dev,>=1.34.1->google-cloud-aiplatform) (1.64.1)\n",
            "Requirement already satisfied: grpcio-status<2.0.dev0,>=1.33.2 in /usr/local/lib/python3.10/dist-packages (from google-api-core[grpc]!=2.0.*,!=2.1.*,!=2.2.*,!=2.3.*,!=2.4.*,!=2.5.*,!=2.6.*,!=2.7.*,<3.0.0dev,>=1.34.1->google-cloud-aiplatform) (1.48.2)\n",
            "Requirement already satisfied: cachetools<6.0,>=2.0.0 in /usr/local/lib/python3.10/dist-packages (from google-auth<3.0.0dev,>=2.14.1->google-cloud-aiplatform) (5.5.0)\n",
            "Requirement already satisfied: pyasn1-modules>=0.2.1 in /usr/local/lib/python3.10/dist-packages (from google-auth<3.0.0dev,>=2.14.1->google-cloud-aiplatform) (0.4.1)\n",
            "Requirement already satisfied: rsa<5,>=3.1.4 in /usr/local/lib/python3.10/dist-packages (from google-auth<3.0.0dev,>=2.14.1->google-cloud-aiplatform) (4.9)\n",
            "Requirement already satisfied: google-cloud-core<3.0.0dev,>=1.6.0 in /usr/local/lib/python3.10/dist-packages (from google-cloud-bigquery!=3.20.0,<4.0.0dev,>=1.15.0->google-cloud-aiplatform) (2.4.1)\n",
            "Requirement already satisfied: google-resumable-media<3.0dev,>=0.6.0 in /usr/local/lib/python3.10/dist-packages (from google-cloud-bigquery!=3.20.0,<4.0.0dev,>=1.15.0->google-cloud-aiplatform) (2.7.2)\n",
            "Requirement already satisfied: python-dateutil<3.0dev,>=2.7.2 in /usr/local/lib/python3.10/dist-packages (from google-cloud-bigquery!=3.20.0,<4.0.0dev,>=1.15.0->google-cloud-aiplatform) (2.8.2)\n",
            "Requirement already satisfied: grpc-google-iam-v1<1.0.0dev,>=0.12.4 in /usr/local/lib/python3.10/dist-packages (from google-cloud-resource-manager<3.0.0dev,>=1.3.3->google-cloud-aiplatform) (0.13.1)\n",
            "Requirement already satisfied: annotated-types>=0.6.0 in /usr/local/lib/python3.10/dist-packages (from pydantic<3->google-cloud-aiplatform) (0.7.0)\n",
            "Requirement already satisfied: pydantic-core==2.23.4 in /usr/local/lib/python3.10/dist-packages (from pydantic<3->google-cloud-aiplatform) (2.23.4)\n",
            "Requirement already satisfied: typing-extensions>=4.6.1 in /usr/local/lib/python3.10/dist-packages (from pydantic<3->google-cloud-aiplatform) (4.12.2)\n",
            "Requirement already satisfied: numpy<3,>=1.14 in /usr/local/lib/python3.10/dist-packages (from shapely<3.0.0dev->google-cloud-aiplatform) (1.26.4)\n",
            "Requirement already satisfied: google-crc32c<2.0dev,>=1.0 in /usr/local/lib/python3.10/dist-packages (from google-resumable-media<3.0dev,>=0.6.0->google-cloud-bigquery!=3.20.0,<4.0.0dev,>=1.15.0->google-cloud-aiplatform) (1.6.0)\n",
            "Requirement already satisfied: pyasn1<0.7.0,>=0.4.6 in /usr/local/lib/python3.10/dist-packages (from pyasn1-modules>=0.2.1->google-auth<3.0.0dev,>=2.14.1->google-cloud-aiplatform) (0.6.1)\n",
            "Requirement already satisfied: six>=1.5 in /usr/local/lib/python3.10/dist-packages (from python-dateutil<3.0dev,>=2.7.2->google-cloud-bigquery!=3.20.0,<4.0.0dev,>=1.15.0->google-cloud-aiplatform) (1.16.0)\n",
            "Requirement already satisfied: charset-normalizer<4,>=2 in /usr/local/lib/python3.10/dist-packages (from requests<3.0.0.dev0,>=2.18.0->google-api-core!=2.0.*,!=2.1.*,!=2.2.*,!=2.3.*,!=2.4.*,!=2.5.*,!=2.6.*,!=2.7.*,<3.0.0dev,>=1.34.1->google-api-core[grpc]!=2.0.*,!=2.1.*,!=2.2.*,!=2.3.*,!=2.4.*,!=2.5.*,!=2.6.*,!=2.7.*,<3.0.0dev,>=1.34.1->google-cloud-aiplatform) (3.4.0)\n",
            "Requirement already satisfied: idna<4,>=2.5 in /usr/local/lib/python3.10/dist-packages (from requests<3.0.0.dev0,>=2.18.0->google-api-core!=2.0.*,!=2.1.*,!=2.2.*,!=2.3.*,!=2.4.*,!=2.5.*,!=2.6.*,!=2.7.*,<3.0.0dev,>=1.34.1->google-api-core[grpc]!=2.0.*,!=2.1.*,!=2.2.*,!=2.3.*,!=2.4.*,!=2.5.*,!=2.6.*,!=2.7.*,<3.0.0dev,>=1.34.1->google-cloud-aiplatform) (3.10)\n",
            "Requirement already satisfied: urllib3<3,>=1.21.1 in /usr/local/lib/python3.10/dist-packages (from requests<3.0.0.dev0,>=2.18.0->google-api-core!=2.0.*,!=2.1.*,!=2.2.*,!=2.3.*,!=2.4.*,!=2.5.*,!=2.6.*,!=2.7.*,<3.0.0dev,>=1.34.1->google-api-core[grpc]!=2.0.*,!=2.1.*,!=2.2.*,!=2.3.*,!=2.4.*,!=2.5.*,!=2.6.*,!=2.7.*,<3.0.0dev,>=1.34.1->google-cloud-aiplatform) (2.2.3)\n",
            "Requirement already satisfied: certifi>=2017.4.17 in /usr/local/lib/python3.10/dist-packages (from requests<3.0.0.dev0,>=2.18.0->google-api-core!=2.0.*,!=2.1.*,!=2.2.*,!=2.3.*,!=2.4.*,!=2.5.*,!=2.6.*,!=2.7.*,<3.0.0dev,>=1.34.1->google-api-core[grpc]!=2.0.*,!=2.1.*,!=2.2.*,!=2.3.*,!=2.4.*,!=2.5.*,!=2.6.*,!=2.7.*,<3.0.0dev,>=1.34.1->google-cloud-aiplatform) (2024.8.30)\n"
          ]
        }
      ]
    },
    {
      "cell_type": "code",
      "source": [
        "from google.colab import auth\n",
        "auth.authenticate_user()\n",
        "!gcloud projects get-iam-policy empowerme-bb3c5"
      ],
      "metadata": {
        "colab": {
          "base_uri": "https://localhost:8080/"
        },
        "id": "1GCmcGdWWwKg",
        "outputId": "e6fa6a18-4de9-45b1-a241-5eae344a3f5d"
      },
      "execution_count": 12,
      "outputs": [
        {
          "output_type": "stream",
          "name": "stdout",
          "text": [
            "\u001b[1;31mERROR:\u001b[0m (gcloud.projects.get-iam-policy) [suzukiairi117@gmail.com] does not have permission to access projects instance [empowerme-bb3c5:getIamPolicy] (or it may not exist): The caller does not have permission. This command is authenticated as suzukiairi117@gmail.com which is the active account specified by the [core/account] property\n"
          ]
        }
      ]
    },
    {
      "cell_type": "code",
      "source": [
        "import vertexai\n",
        "from vertexai.preview.vision_models import ImageGenerationModel\n",
        "\n",
        "project_id = \"empowerme-bb3c5\"\n",
        "\n",
        "vertexai.init(project=project_id, location=\"us-central1\")\n",
        "\n",
        "generation_model = ImageGenerationModel.from_pretrained(\"imagen-3.0-generate-001\")\n",
        "\n",
        "prompt = \"\"\"\n",
        "木製のキッチンテーブルの上に置かれた料理本の写実的な画像です。表紙は正面を向いており、同じようなテーブルに座っている笑顔の家族が描かれています。頭上の柔らかい照明がシーンを照らしており、料理本が画像の中心となっています。\n",
        "\"\"\"\n",
        "\n",
        "image = generation_model.generate_images(\n",
        "    prompt=prompt,\n",
        "    number_of_images=1,\n",
        "    aspect_ratio=\"1:1\",\n",
        "    safety_filter_level=\"block_some\",\n",
        "    person_generation=\"allow_all\",\n",
        ")\n",
        "\n",
        "# OPTIONAL: 生成された画像をノートブックで表示\n",
        "image[0].show()"
      ],
      "metadata": {
        "colab": {
          "base_uri": "https://localhost:8080/",
          "height": 795
        },
        "id": "1AgGzHn8RbeI",
        "outputId": "e750f500-f907-4eff-a74c-1180cc7b5c4e"
      },
      "execution_count": 16,
      "outputs": [
        {
          "output_type": "error",
          "ename": "PermissionDenied",
          "evalue": "403 Permission 'aiplatform.endpoints.predict' denied on resource '//aiplatform.googleapis.com/projects/empowerme-bb3c5/locations/us-central1/publishers/google/models/imagen-3.0-generate-001@default' (or it may not exist). [reason: \"IAM_PERMISSION_DENIED\"\ndomain: \"aiplatform.googleapis.com\"\nmetadata {\n  key: \"permission\"\n  value: \"aiplatform.endpoints.predict\"\n}\nmetadata {\n  key: \"resource\"\n  value: \"projects/empowerme-bb3c5/locations/us-central1/publishers/google/models/imagen-3.0-generate-001@default\"\n}\n]",
          "traceback": [
            "\u001b[0;31m---------------------------------------------------------------------------\u001b[0m",
            "\u001b[0;31m_InactiveRpcError\u001b[0m                         Traceback (most recent call last)",
            "\u001b[0;32m/usr/local/lib/python3.10/dist-packages/google/api_core/grpc_helpers.py\u001b[0m in \u001b[0;36merror_remapped_callable\u001b[0;34m(*args, **kwargs)\u001b[0m\n\u001b[1;32m     75\u001b[0m         \u001b[0;32mtry\u001b[0m\u001b[0;34m:\u001b[0m\u001b[0;34m\u001b[0m\u001b[0;34m\u001b[0m\u001b[0m\n\u001b[0;32m---> 76\u001b[0;31m             \u001b[0;32mreturn\u001b[0m \u001b[0mcallable_\u001b[0m\u001b[0;34m(\u001b[0m\u001b[0;34m*\u001b[0m\u001b[0margs\u001b[0m\u001b[0;34m,\u001b[0m \u001b[0;34m**\u001b[0m\u001b[0mkwargs\u001b[0m\u001b[0;34m)\u001b[0m\u001b[0;34m\u001b[0m\u001b[0;34m\u001b[0m\u001b[0m\n\u001b[0m\u001b[1;32m     77\u001b[0m         \u001b[0;32mexcept\u001b[0m \u001b[0mgrpc\u001b[0m\u001b[0;34m.\u001b[0m\u001b[0mRpcError\u001b[0m \u001b[0;32mas\u001b[0m \u001b[0mexc\u001b[0m\u001b[0;34m:\u001b[0m\u001b[0;34m\u001b[0m\u001b[0;34m\u001b[0m\u001b[0m\n",
            "\u001b[0;32m/usr/local/lib/python3.10/dist-packages/grpc/_channel.py\u001b[0m in \u001b[0;36m__call__\u001b[0;34m(self, request, timeout, metadata, credentials, wait_for_ready, compression)\u001b[0m\n\u001b[1;32m   1180\u001b[0m         )\n\u001b[0;32m-> 1181\u001b[0;31m         \u001b[0;32mreturn\u001b[0m \u001b[0m_end_unary_response_blocking\u001b[0m\u001b[0;34m(\u001b[0m\u001b[0mstate\u001b[0m\u001b[0;34m,\u001b[0m \u001b[0mcall\u001b[0m\u001b[0;34m,\u001b[0m \u001b[0;32mFalse\u001b[0m\u001b[0;34m,\u001b[0m \u001b[0;32mNone\u001b[0m\u001b[0;34m)\u001b[0m\u001b[0;34m\u001b[0m\u001b[0;34m\u001b[0m\u001b[0m\n\u001b[0m\u001b[1;32m   1182\u001b[0m \u001b[0;34m\u001b[0m\u001b[0m\n",
            "\u001b[0;32m/usr/local/lib/python3.10/dist-packages/grpc/_channel.py\u001b[0m in \u001b[0;36m_end_unary_response_blocking\u001b[0;34m(state, call, with_call, deadline)\u001b[0m\n\u001b[1;32m   1005\u001b[0m     \u001b[0;32melse\u001b[0m\u001b[0;34m:\u001b[0m\u001b[0;34m\u001b[0m\u001b[0;34m\u001b[0m\u001b[0m\n\u001b[0;32m-> 1006\u001b[0;31m         \u001b[0;32mraise\u001b[0m \u001b[0m_InactiveRpcError\u001b[0m\u001b[0;34m(\u001b[0m\u001b[0mstate\u001b[0m\u001b[0;34m)\u001b[0m  \u001b[0;31m# pytype: disable=not-instantiable\u001b[0m\u001b[0;34m\u001b[0m\u001b[0;34m\u001b[0m\u001b[0m\n\u001b[0m\u001b[1;32m   1007\u001b[0m \u001b[0;34m\u001b[0m\u001b[0m\n",
            "\u001b[0;31m_InactiveRpcError\u001b[0m: <_InactiveRpcError of RPC that terminated with:\n\tstatus = StatusCode.PERMISSION_DENIED\n\tdetails = \"Permission 'aiplatform.endpoints.predict' denied on resource '//aiplatform.googleapis.com/projects/empowerme-bb3c5/locations/us-central1/publishers/google/models/imagen-3.0-generate-001@default' (or it may not exist).\"\n\tdebug_error_string = \"UNKNOWN:Error received from peer ipv4:74.125.26.95:443 {created_time:\"2024-10-27T14:32:24.528312416+00:00\", grpc_status:7, grpc_message:\"Permission \\'aiplatform.endpoints.predict\\' denied on resource \\'//aiplatform.googleapis.com/projects/empowerme-bb3c5/locations/us-central1/publishers/google/models/imagen-3.0-generate-001@default\\' (or it may not exist).\"}\"\n>",
            "\nThe above exception was the direct cause of the following exception:\n",
            "\u001b[0;31mPermissionDenied\u001b[0m                          Traceback (most recent call last)",
            "\u001b[0;32m<ipython-input-16-6d1130781447>\u001b[0m in \u001b[0;36m<cell line: 14>\u001b[0;34m()\u001b[0m\n\u001b[1;32m     12\u001b[0m \"\"\"\n\u001b[1;32m     13\u001b[0m \u001b[0;34m\u001b[0m\u001b[0m\n\u001b[0;32m---> 14\u001b[0;31m image = generation_model.generate_images(\n\u001b[0m\u001b[1;32m     15\u001b[0m     \u001b[0mprompt\u001b[0m\u001b[0;34m=\u001b[0m\u001b[0mprompt\u001b[0m\u001b[0;34m,\u001b[0m\u001b[0;34m\u001b[0m\u001b[0;34m\u001b[0m\u001b[0m\n\u001b[1;32m     16\u001b[0m     \u001b[0mnumber_of_images\u001b[0m\u001b[0;34m=\u001b[0m\u001b[0;36m1\u001b[0m\u001b[0;34m,\u001b[0m\u001b[0;34m\u001b[0m\u001b[0;34m\u001b[0m\u001b[0m\n",
            "\u001b[0;32m/usr/local/lib/python3.10/dist-packages/vertexai/vision_models/_vision_models.py\u001b[0m in \u001b[0;36mgenerate_images\u001b[0;34m(self, prompt, negative_prompt, number_of_images, aspect_ratio, guidance_scale, language, seed, output_gcs_uri, add_watermark, safety_filter_level, person_generation)\u001b[0m\n\u001b[1;32m    681\u001b[0m             \u001b[0mAn\u001b[0m\u001b[0;31m \u001b[0m\u001b[0;31m`\u001b[0m\u001b[0mImageGenerationResponse\u001b[0m\u001b[0;31m`\u001b[0m \u001b[0mobject\u001b[0m\u001b[0;34m.\u001b[0m\u001b[0;34m\u001b[0m\u001b[0;34m\u001b[0m\u001b[0m\n\u001b[1;32m    682\u001b[0m         \"\"\"\n\u001b[0;32m--> 683\u001b[0;31m         return self._generate_images(\n\u001b[0m\u001b[1;32m    684\u001b[0m             \u001b[0mprompt\u001b[0m\u001b[0;34m=\u001b[0m\u001b[0mprompt\u001b[0m\u001b[0;34m,\u001b[0m\u001b[0;34m\u001b[0m\u001b[0;34m\u001b[0m\u001b[0m\n\u001b[1;32m    685\u001b[0m             \u001b[0mnegative_prompt\u001b[0m\u001b[0;34m=\u001b[0m\u001b[0mnegative_prompt\u001b[0m\u001b[0;34m,\u001b[0m\u001b[0;34m\u001b[0m\u001b[0;34m\u001b[0m\u001b[0m\n",
            "\u001b[0;32m/usr/local/lib/python3.10/dist-packages/vertexai/vision_models/_vision_models.py\u001b[0m in \u001b[0;36m_generate_images\u001b[0;34m(self, prompt, negative_prompt, number_of_images, width, height, aspect_ratio, guidance_scale, seed, base_image, mask, edit_mode, mask_mode, segmentation_classes, mask_dilation, product_position, output_mime_type, compression_quality, language, output_gcs_uri, add_watermark, safety_filter_level, person_generation)\u001b[0m\n\u001b[1;32m    603\u001b[0m             \u001b[0mshared_generation_parameters\u001b[0m\u001b[0;34m[\u001b[0m\u001b[0;34m\"person_generation\"\u001b[0m\u001b[0;34m]\u001b[0m \u001b[0;34m=\u001b[0m \u001b[0mperson_generation\u001b[0m\u001b[0;34m\u001b[0m\u001b[0;34m\u001b[0m\u001b[0m\n\u001b[1;32m    604\u001b[0m \u001b[0;34m\u001b[0m\u001b[0m\n\u001b[0;32m--> 605\u001b[0;31m         response = self._endpoint.predict(\n\u001b[0m\u001b[1;32m    606\u001b[0m             \u001b[0minstances\u001b[0m\u001b[0;34m=\u001b[0m\u001b[0;34m[\u001b[0m\u001b[0minstance\u001b[0m\u001b[0;34m]\u001b[0m\u001b[0;34m,\u001b[0m\u001b[0;34m\u001b[0m\u001b[0;34m\u001b[0m\u001b[0m\n\u001b[1;32m    607\u001b[0m             \u001b[0mparameters\u001b[0m\u001b[0;34m=\u001b[0m\u001b[0mparameters\u001b[0m\u001b[0;34m,\u001b[0m\u001b[0;34m\u001b[0m\u001b[0;34m\u001b[0m\u001b[0m\n",
            "\u001b[0;32m/usr/local/lib/python3.10/dist-packages/google/cloud/aiplatform/models.py\u001b[0m in \u001b[0;36mpredict\u001b[0;34m(self, instances, parameters, timeout, use_raw_predict, use_dedicated_endpoint)\u001b[0m\n\u001b[1;32m   2291\u001b[0m \u001b[0;34m\u001b[0m\u001b[0m\n\u001b[1;32m   2292\u001b[0m         \u001b[0;32melse\u001b[0m\u001b[0;34m:\u001b[0m\u001b[0;34m\u001b[0m\u001b[0;34m\u001b[0m\u001b[0m\n\u001b[0;32m-> 2293\u001b[0;31m             prediction_response = self._prediction_client.predict(\n\u001b[0m\u001b[1;32m   2294\u001b[0m                 \u001b[0mendpoint\u001b[0m\u001b[0;34m=\u001b[0m\u001b[0mself\u001b[0m\u001b[0;34m.\u001b[0m\u001b[0m_gca_resource\u001b[0m\u001b[0;34m.\u001b[0m\u001b[0mname\u001b[0m\u001b[0;34m,\u001b[0m\u001b[0;34m\u001b[0m\u001b[0;34m\u001b[0m\u001b[0m\n\u001b[1;32m   2295\u001b[0m                 \u001b[0minstances\u001b[0m\u001b[0;34m=\u001b[0m\u001b[0minstances\u001b[0m\u001b[0;34m,\u001b[0m\u001b[0;34m\u001b[0m\u001b[0;34m\u001b[0m\u001b[0m\n",
            "\u001b[0;32m/usr/local/lib/python3.10/dist-packages/google/cloud/aiplatform_v1/services/prediction_service/client.py\u001b[0m in \u001b[0;36mpredict\u001b[0;34m(self, request, endpoint, instances, parameters, retry, timeout, metadata)\u001b[0m\n\u001b[1;32m    846\u001b[0m \u001b[0;34m\u001b[0m\u001b[0m\n\u001b[1;32m    847\u001b[0m         \u001b[0;31m# Send the request.\u001b[0m\u001b[0;34m\u001b[0m\u001b[0;34m\u001b[0m\u001b[0m\n\u001b[0;32m--> 848\u001b[0;31m         response = rpc(\n\u001b[0m\u001b[1;32m    849\u001b[0m             \u001b[0mrequest\u001b[0m\u001b[0;34m,\u001b[0m\u001b[0;34m\u001b[0m\u001b[0;34m\u001b[0m\u001b[0m\n\u001b[1;32m    850\u001b[0m             \u001b[0mretry\u001b[0m\u001b[0;34m=\u001b[0m\u001b[0mretry\u001b[0m\u001b[0;34m,\u001b[0m\u001b[0;34m\u001b[0m\u001b[0;34m\u001b[0m\u001b[0m\n",
            "\u001b[0;32m/usr/local/lib/python3.10/dist-packages/google/api_core/gapic_v1/method.py\u001b[0m in \u001b[0;36m__call__\u001b[0;34m(self, timeout, retry, compression, *args, **kwargs)\u001b[0m\n\u001b[1;32m    129\u001b[0m             \u001b[0mkwargs\u001b[0m\u001b[0;34m[\u001b[0m\u001b[0;34m\"compression\"\u001b[0m\u001b[0;34m]\u001b[0m \u001b[0;34m=\u001b[0m \u001b[0mcompression\u001b[0m\u001b[0;34m\u001b[0m\u001b[0;34m\u001b[0m\u001b[0m\n\u001b[1;32m    130\u001b[0m \u001b[0;34m\u001b[0m\u001b[0m\n\u001b[0;32m--> 131\u001b[0;31m         \u001b[0;32mreturn\u001b[0m \u001b[0mwrapped_func\u001b[0m\u001b[0;34m(\u001b[0m\u001b[0;34m*\u001b[0m\u001b[0margs\u001b[0m\u001b[0;34m,\u001b[0m \u001b[0;34m**\u001b[0m\u001b[0mkwargs\u001b[0m\u001b[0;34m)\u001b[0m\u001b[0;34m\u001b[0m\u001b[0;34m\u001b[0m\u001b[0m\n\u001b[0m\u001b[1;32m    132\u001b[0m \u001b[0;34m\u001b[0m\u001b[0m\n\u001b[1;32m    133\u001b[0m \u001b[0;34m\u001b[0m\u001b[0m\n",
            "\u001b[0;32m/usr/local/lib/python3.10/dist-packages/google/api_core/grpc_helpers.py\u001b[0m in \u001b[0;36merror_remapped_callable\u001b[0;34m(*args, **kwargs)\u001b[0m\n\u001b[1;32m     76\u001b[0m             \u001b[0;32mreturn\u001b[0m \u001b[0mcallable_\u001b[0m\u001b[0;34m(\u001b[0m\u001b[0;34m*\u001b[0m\u001b[0margs\u001b[0m\u001b[0;34m,\u001b[0m \u001b[0;34m**\u001b[0m\u001b[0mkwargs\u001b[0m\u001b[0;34m)\u001b[0m\u001b[0;34m\u001b[0m\u001b[0;34m\u001b[0m\u001b[0m\n\u001b[1;32m     77\u001b[0m         \u001b[0;32mexcept\u001b[0m \u001b[0mgrpc\u001b[0m\u001b[0;34m.\u001b[0m\u001b[0mRpcError\u001b[0m \u001b[0;32mas\u001b[0m \u001b[0mexc\u001b[0m\u001b[0;34m:\u001b[0m\u001b[0;34m\u001b[0m\u001b[0;34m\u001b[0m\u001b[0m\n\u001b[0;32m---> 78\u001b[0;31m             \u001b[0;32mraise\u001b[0m \u001b[0mexceptions\u001b[0m\u001b[0;34m.\u001b[0m\u001b[0mfrom_grpc_error\u001b[0m\u001b[0;34m(\u001b[0m\u001b[0mexc\u001b[0m\u001b[0;34m)\u001b[0m \u001b[0;32mfrom\u001b[0m \u001b[0mexc\u001b[0m\u001b[0;34m\u001b[0m\u001b[0;34m\u001b[0m\u001b[0m\n\u001b[0m\u001b[1;32m     79\u001b[0m \u001b[0;34m\u001b[0m\u001b[0m\n\u001b[1;32m     80\u001b[0m     \u001b[0;32mreturn\u001b[0m \u001b[0merror_remapped_callable\u001b[0m\u001b[0;34m\u001b[0m\u001b[0;34m\u001b[0m\u001b[0m\n",
            "\u001b[0;31mPermissionDenied\u001b[0m: 403 Permission 'aiplatform.endpoints.predict' denied on resource '//aiplatform.googleapis.com/projects/empowerme-bb3c5/locations/us-central1/publishers/google/models/imagen-3.0-generate-001@default' (or it may not exist). [reason: \"IAM_PERMISSION_DENIED\"\ndomain: \"aiplatform.googleapis.com\"\nmetadata {\n  key: \"permission\"\n  value: \"aiplatform.endpoints.predict\"\n}\nmetadata {\n  key: \"resource\"\n  value: \"projects/empowerme-bb3c5/locations/us-central1/publishers/google/models/imagen-3.0-generate-001@default\"\n}\n]"
          ]
        }
      ]
    }
  ],
  "metadata": {
    "accelerator": "GPU",
    "colab": {
      "gpuType": "T4",
      "machine_shape": "hm",
      "provenance": []
    },
    "kernelspec": {
      "display_name": "Python 3",
      "name": "python3"
    },
    "language_info": {
      "name": "python"
    }
  },
  "nbformat": 4,
  "nbformat_minor": 0
}